Workbook

Sheet Raw Data
A1: Customer ID | B1: Customer Name | C1: Email | D1: Phone | E1: City | F1: Order Date | G1: Order Amount | H1: Order Status
A2: C109 | B2: Dakota Jackson | C2: dakota.jackson109@example.com | D2: 4045551109 | E2: Kennesaw | F2: 04/21/2026 | G2: 241.95 | H2: Cancelled
A3: C055 | B3: Casey Martin | C3: casey.martin55@example.com | D3: 4045551055 | E3: kennesaw | F3: 07/18/2026 | G3: 89.47 | H3: Completed
A4: C028 | B4: Kendall Moore | C4: kendall.moore28@example.com | D4: (404) 555-1028 | E4: Smyrna | F4: 06/28/2026 | G4: 261.06 | H4: Processing
A5: C004 | B5: Sydney Wilson | C5: sydney.wilson4@example.com | D5: 4045551004 | E5: Atlanta | F5: 07/09/2026 | G5: 105.24 | H5: Completed
A6: C044 | B6: Kendall White | C6: kendall.white44@example.com | D6: 4045551044 | E6: decatur | F6: 03/13/2026 | G6: 162.02 | H6: Cancelled
A7: C026 | B7: ROBIN JACKSON | C7: robin.jackson26@example.com | D7: 4045551026 | E7: Marietta | F7: 08/22/2026 | G7: 38.48 | H7: Processing
A8: C076 | B8: Robin White | D8: 4045551076 | E8: Decatur | F8: 04/24/2026 | G8: 116.07 | H8: Completed
A9: C086 | B9: Robin Moore | C9: robin.moore86@example.com | D9: 4045551086 | E9: Roswell | F9: 02/16/2026 | G9: 265.53 | H9: Completed
A10: C016 | B10: Quinn Thompson | C10: quinn.thompson16@example.com | D10: 4045551016 | E10: Douglasville | F10: Jun 23, 2026 | G10: 250.38 | H10: cancelled
A11: C125 | B11: Reese Miller | C11: reese.miller125@example.com | D11: 4045551125 | E11: Sandy Springs | F11: 03/28/2026 | G11: 174.03 | H11: Cancelled
A12: C058 | B12: Dakota Wilson | C12: dakota.wilson58@example.com | D12: 4045551058 | E12: Marietta | F12: 05/22/2026 | H12: Cancelled
A13: C127 | B13: Blake Thompson | C13: blake.thompson127@example.com | D13: 4045551127 | E13: Smyrna | F13: 09/14/2026 | G13: 149.17 | H13: Processing
A14: C036 | B14: Alex White | C14: alex.white36@example.com | D14: 404-555-1036 | E14: Marietta | F14: 2026-09-05 | G14: 186.52 | H14: Cancelled
A15: C073 | B15: Parker Taylor | C15: parker.taylor73@example.com | D15: 4045551073 | E15: Decatur | F15: 04/25/2026 | G15: 217.26 | H15: Pending
A16: C005 | B16: Drew Wilson | C16: drew.wilson5@example.com | D16: 4045551005 | E16: Sandy Springs | F16: 04/12/2026 | G16: 213.82 | H16: Processing
A17: C031 | B17: Morgan Harris | C17: morgan.harris31@example.com | D17: 4045551031 | E17: Marietta | F17: 08/13/2026 | G17: 123.49 | H17: Pending
A18: C079 | B18: Reese Anderson | C18: reese.anderson79@example.com | D18: 4045551079 | E18: Sandy Springs | F18: 03/15/2026 | G18: 95.32 | H18: Cancelled
A19: C068 | B19: Morgan Davis | C19: morgan.davis68@example.com | D19: 4045551068 | E19: Smyrna | F19: 06/19/2026 | G19: 306.23 | H19: Processing
A20: C041 | B20: Kendall Johnson | C20: kendall.johnson41@example.com | D20: 4045551041 | E20: Douglasville | F20: 03/01/2026 | G20: 45.08 | H20: Completed
A21: C062 | B21: Quinn Harris | C21: quinn.harris62@example.com | D21: 4045551062 | E21: Sandy Springs | F21: 03/11/2026 | G21: 309.8 | H21: Pending
A22: C126 | B22: Riley Taylor | C22: riley.taylor126@example.com | D22: (404) 555-1126 | E22: Marietta | F22: 2026-08-07 | G22: 221.79 | H22: PENDING
A23: C027 | B23: Blake Johnson | C23: blake.johnson27@example.com | D23: 404-555-1027 | E23: Kennesaw | F23: 2026-02-18 | G23: 156.72 | H23: Completed
A24: C100 | B24: Alex Jackson | C24: alex.jackson100@example.com | D24: 4045551100 | E24: Smyrna | F24: 07/09/2026 | G24: 287.4 | H24: Processing
... A44: C112 | B44: Reese Harris | C44: reese.harris112@example.com | D44: (404) 555-1112 | E44: Douglasville | F44: May 21, 2026 | G44: 270.66 | H44: cancelled
A45: C038 | B45: Quinn Harris | D45: 4045551038 | E45: Sandy Springs | F45: 09/25/2026 | G45: 26.07 | H45: Processing
A46: C082 | B46: Quinn Harris | C46: quinn.harris82@example.com | D46: 4045551082 | E46: Decatur | F46: 07/27/2026 | G46: 264.96 | H46: Completed
A47: C118 | B47: Alex Thompson | C47: alex.thompson118@example.com | D47: 4045551118 | E47: Marietta | F47: 03/18/2026 | G47: 228.4 | H47: Completed
A48: C080 | B48: Taylor Davis | C48: taylor.davis80@example.com | D48: 4045551080 | E48: Decatur | F48: May 04, 2026 | G48: 140.69 | H48: completed
A49: C042 | B49: Kendall Taylor | C49: kendall.taylor42@example.com | D49: (404) 555-1042 | E49: Kennesaw | F49: 2026-07-24 | G49: 95.97 | H49: COMPLETED
A50: C066 | B50: Jordan Harris | C50: jordan.harris66@example.com | D50: 4045551066 | E50: douglasville | F50: 2026-09-24 | G50: 22.87 | H50: Processing
A51: C049 | B51: Kendall White | C51: kendall.white49@example.com | D51: (404) 555-1049 | E51: Kennesaw | F51: 04/16/2026 | G51: 226.45 | H51: Processing
A52: C070 | B52: Riley Jackson | C52: riley.jackson70@example.com | D52: (404) 555-1070 | E52: Atlanta | F52: 03/26/2026 | G52: 254.93 | H52: Cancelled
A53: C009 | B53: Robin Martin | C53: robin.martin9@example.com | D53: 404-555-1009 | E53: Kennesaw | F53: 2026-04-04 | G53: 278.62 | H53: Cancelled
A54: C076 | B54: Robin White | D54: 4045551076 | E54: Decatur | F54: 04/24/2026 | G54: 116.07 | H54: Completed
A55: C069 | B55: Casey Anderson | C55: casey.anderson69@example.com | D55: 4045551069 | E55: ATL | F55: 2026-04-05 | G55: 18.15 | H55: Pending
A56: C072 | B56: Drew Thompson | C56: drew.thompson72@example.com | D56: 404-555-1072 | E56: Decatur | F56: 2026-05-25 | G56: 221.76 | H56: processing
A57: C106 | B57: Jordan Davis | C57: jordan.davis106@example.com | D57: 4045551106 | E57: Marietta | F57: 02/03/2026 | G57: 30.52 | H57: Cancelled
A58: C056 | B58: Reese White | C58: reese.white56@example.com | D58: (404) 555-1056 | E58: Kennesaw | F58: 09/18/2026 | G58: 157.88 | H58: completed
A59: C134 | B59: Jamie Anderson | C59: jamie.anderson134@example.com | D59: 4045551134 | E59: Atlanta | F59: 07/16/2026 | G59: 215.12 | H59: Completed
...

Sheet Cleaned Data
A1: Customer ID | B1: Customer Name | C1: Email | D1: Phone | E1: City | F1: Order Date | G1: Order Amount | H1: Order Status | I1: Duplicate Check | J1: Exact Duplicate Check | K1: Data Quality Status
A2: C051 | B2: Morgan Brown | C2: morgan.brown51@example.com | D2: (404) 555-1051 | E2: Decatur | F2: 46027 | G2: 48.14 | H2: Processing | I2: =COUNTIF($A$2:$A$141,A2) -> 1 | J2: =COUNTIFS(A$2:A2,A2,B$2:B2,B2,C$2:C2,IF(C2="","=",C2),D$2:D2,IF(D2="","=",D2),E$2:E2,IF(E2="","=",E2),F$2:F2,F2,G$2:G2,IF(G2="","=",G2),H$2:H2,H2) -> 1 | K2: =IF(OR(C2="",G2="",NOT(ISNUMBER(G2)),AND(ISNUMBER(G2),G2<=0)),"Needs Review","Valid") -> Valid
A3: C074 | B3: Sam Williams | C3: sam.williams74@example.com | D3: (404) 555-1074 | E3: Decatur | F3: 46028 | G3: 75.96 | H3: Completed | I3: =COUNTIF($A$2:$A$141,A3) -> 1 | J3: =COUNTIFS(A$2:A3,A3,B$2:B3,B3,C$2:C3,IF(C3="","=",C3),D$2:D3,IF(D3="","=",D3),E$2:E3,IF(E3="","=",E3),F$2:F3,F3,G$2:G3,IF(G3="","=",G3),H$2:H3,H3) -> 1 | K3: =IF(OR(C3="",G3="",NOT(ISNUMBER(G3)),AND(ISNUMBER(G3),G3<=0)),"Needs Review","Valid") -> Valid
A4: C015 | B4: Parker Thomas | C4: parker.thomas15@example.com | D4: (404) 555-1015 | E4: Decatur | F4: 46039 | G4: 222.88 | H4: Processing | I4: =COUNTIF($A$2:$A$141,A4) -> 1 | J4: =COUNTIFS(A$2:A4,A4,B$2:B4,B4,C$2:C4,IF(C4="","=",C4),D$2:D4,IF(D4="","=",D4),E$2:E4,IF(E4="","=",E4),F$2:F4,F4,G$2:G4,IF(G4="","=",G4),H$2:H4,H4) -> 1 | K4: =IF(OR(C4="",G4="",NOT(ISNUMBER(G4)),AND(ISNUMBER(G4),G4<=0)),"Needs Review","Valid") -> Valid
A5: C077 | B5: Parker Brown | C5: parker.brown77@example.com | D5: (404) 555-1077 | E5: Sandy Springs | F5: 46040 | G5: 319.39 | H5: Processing | I5: =COUNTIF($A$2:$A$141,A5) -> 1 | J5: =COUNTIFS(A$2:A5,A5,B$2:B5,B5,C$2:C5,IF(C5="","=",C5),D$2:D5,IF(D5="","=",D5),E$2:E5,IF(E5="","=",E5),F$2:F5,F5,G$2:G5,IF(G5="","=",G5),H$2:H5,H5) -> 1 | K5: =IF(OR(C5="",G5="",NOT(ISNUMBER(G5)),AND(ISNUMBER(G5),G5<=0)),"Needs Review","Valid") -> Valid
A6: C136 | B6: Devin Johnson | C6: devin.johnson136@example.com | D6: (404) 555-1136 | E6: Roswell | F6: 46042 | G6: 124.27 | H6: pending | I6: =COUNTIF($A$2:$A$141,A6) -> 1 | J6: =COUNTIFS(A$2:A6,A6,B$2:B6,B6,C$2:C6,IF(C6="","=",C6),D$2:D6,IF(D6="","=",D6),E$2:E6,IF(E6="","=",E6),F$2:F6,F6,G$2:G6,IF(G6="","=",G6),H$2:H6,H6) -> 1 | K6: =IF(OR(C6="",G6="",NOT(ISNUMBER(G6)),AND(ISNUMBER(G6),G6<=0)),"Needs Review","Valid") -> Valid
A7: C120 | B7: Blake Thompson | C7: blake.thompson120@example.com | D7: (404) 555-1120 | E7: Decatur | F7: 46043 | G7: 116.32 | H7: completed | I7: =COUNTIF($A$2:$A$141,A7) -> 1 | J7: =COUNTIFS(A$2:A7,A7,B$2:B7,B7,C$2:C7,IF(C7="","=",C7),D$2:D7,IF(D7="","=",D7),E$2:E7,IF(E7="","=",E7),F$2:F7,F7,G$2:G7,IF(G7="","=",G7),H$2:H7,H7) -> 1 | K7: =IF(OR(C7="",G7="",NOT(ISNUMBER(G7)),AND(ISNUMBER(G7),G7<=0)),"Needs Review","Valid") -> Valid
A8: C067 | B8: Riley Taylor | C8: riley.taylor67@example.com | D8: (404) 555-1067 | E8: Marietta | F8: 46043 | G8: 138.97 | H8: Cancelled | I8: =COUNTIF($A$2:$A$141,A8) -> 1 | J8: =COUNTIFS(A$2:A8,A8,B$2:B8,B8,C$2:C8,IF(C8="","=",C8),D$2:D8,IF(D8="","=",D8),E$2:E8,IF(E8="","=",E8),F$2:F8,F8,G$2:G8,IF(G8="","=",G8),H$2:H8,H8) -> 1 | K8: =IF(OR(C8="",G8="",NOT(ISNUMBER(G8)),AND(ISNUMBER(G8),G8<=0)),"Needs Review","Valid") -> Valid
A9: C104 | B9: Parker Jackson | C9: parker.jackson104@example.com | D9: (404) 555-1104 | E9: Decatur | F9: 46048 | G9: 116.35 | H9: cancelled | I9: =COUNTIF($A$2:$A$141,A9) -> 1 | J9: =COUNTIFS(A$2:A9,A9,B$2:B9,B9,C$2:C9,IF(C9="","=",C9),D$2:D9,IF(D9="","=",D9),E$2:E9,IF(E9="","=",E9),F$2:F9,F9,G$2:G9,IF(G9="","=",G9),H$2:H9,H9) -> 1 | K9: =IF(OR(C9="",G9="",NOT(ISNUMBER(G9)),AND(ISNUMBER(G9),G9<=0)),"Needs Review","Valid") -> Valid
A10: C017 | B10: Dakota Brown | C10: dakota.brown17@example.com | D10: (404) 555-1017 | E10: Smyrna | F10: 46050 | G10: 295.43 | H10: Cancelled | I10: =COUNTIF($A$2:$A$141,A10) -> 1 | J10: =COUNTIFS(A$2:A10,A10,B$2:B10,B10,C$2:C10,IF(C10="","=",C10),D$2:D10,IF(D10="","=",D10),E$2:E10,IF(E10="","=",E10),F$2:F10,F10,G$2:G10,IF(G10="","=",G10),H$2:H10,H10) -> 1 | K10: =IF(OR(C10="",G10="",NOT(ISNUMBER(G10)),AND(ISNUMBER(G10),G10<=0)),"Needs Review","Valid") -> Valid
A11: C106 | B11: Jordan Davis | C11: jordan.davis106@example.com | D11: (404) 555-1106 | E11: Marietta | F11: 46056 | G11: 30.52 | H11: Cancelled | I11: =COUNTIF($A$2:$A$141,A11) -> 1 | J11: =COUNTIFS(A$2:A11,A11,B$2:B11,B11,C$2:C11,IF(C11="","=",C11),D$2:D11,IF(D11="","=",D11),E$2:E11,IF(E11="","=",E11),F$2:F11,F11,G$2:G11,IF(G11="","=",G11),H$2:H11,H11) -> 1 | K11: =IF(OR(C11="",G11="",NOT(ISNUMBER(G11)),AND(ISNUMBER(G11),G11<=0)),"Needs Review","Valid") -> Valid
A12: C103 | B12: Quinn Wilson | C12: quinn.wilson103@example.com | D12: (404) 555-1103 | E12: Marietta | F12: 46061 | G12: 15.63 | H12: Completed | I12: =COUNTIF($A$2:$A$141,A12) -> 1 | J12: =COUNTIFS(A$2:A12,A12,B$2:B12,B12,C$2:C12,IF(C12="","=",C12),D$2:D12,IF(D12="","=",D12),E$2:E12,IF(E12="","=",E12),F$2:F12,F12,G$2:G12,IF(G12="","=",G12),H$2:H12,H12) -> 1 | K12: =IF(OR(C12="",G12="",NOT(ISNUMBER(G12)),AND(ISNUMBER(G12),G12<=0)),"Needs Review","Valid") -> Valid
A13: C081 | B13: Morgan Williams | C13: morgan.williams81@example.com | D13: (404) 555-1081 | E13: Douglasville | F13: 46061 | G13: 68.23 | H13: Completed | I13: =COUNTIF($A$2:$A$141,A13) -> 1 | J13: =COUNTIFS(A$2:A13,A13,B$2:B13,B13,C$2:C13,IF(C13="","=",C13),D$2:D13,IF(D13="","=",D13),E$2:E13,IF(E13="","=",E13),F$2:F13,F13,G$2:G13,IF(G13="","=",G13),H$2:H13,H13) -> 1 | K13: =IF(OR(C13="",G13="",NOT(ISNUMBER(G13)),AND(ISNUMBER(G13),G13<=0)),"Needs Review","Valid") -> Valid
A14: C116 | B14: Kendall Williams | C14: kendall.williams116@example.com | D14: (404) 555-1116 | E14: Sandy Springs | F14: 46063 | H14: Processing | I14: =COUNTIF($A$2:$A$141,A14) -> 1 | J14: =COUNTIFS(A$2:A14,A14,B$2:B14,B14,C$2:C14,IF(C14="","=",C14),D$2:D14,IF(D14="","=",D14),E$2:E14,IF(E14="","=",E14),F$2:F14,F14,G$2:G14,IF(G14="","=",G14),H$2:H14,H14) -> 1 | K14: =IF(OR(C14="",G14="",NOT(ISNUMBER(G14)),AND(ISNUMBER(G14),G14<=0)),"Needs Review","Valid") -> Needs Review
A15: C032 | B15: Reese Taylor | C15: reese.taylor32@example.com | D15: (404) 555-1032 | E15: Decatur | F15: 46063 | G15: 194.28 | H15: completed | I15: =COUNTIF($A$2:$A$141,A15) -> 1 | J15: =COUNTIFS(A$2:A15,A15,B$2:B15,B15,C$2:C15,IF(C15="","=",C15),D$2:D15,IF(D15="","=",D15),E$2:E15,IF(E15="","=",E15),F$2:F15,F15,G$2:G15,IF(G15="","=",G15),H$2:H15,H15) -> 1 | K15: =IF(OR(C15="",G15="",NOT(ISNUMBER(G15)),AND(ISNUMBER(G15),G15<=0)),"Needs Review","Valid") -> Valid
A16: C014 | B16: Kendall Martin | C16: kendall.martin14@example.com | D16: (404) 555-1014 | E16: Decatur | F16: 46064 | G16: 292.79 | H16: Processing | I16: =COUNTIF($A$2:$A$141,A16) -> 1 | J16: =COUNTIFS(A$2:A16,A16,B$2:B16,B16,C$2:C16,IF(C16="","=",C16),D$2:D16,IF(D16="","=",D16),E$2:E16,IF(E16="","=",E16),F$2:F16,F16,G$2:G16,IF(G16="","=",G16),H$2:H16,H16) -> 1 | K16: =IF(OR(C16="",G16="",NOT(ISNUMBER(G16)),AND(ISNUMBER(G16),G16<=0)),"Needs Review","Valid") -> Valid
A17: C012 | B17: Sydney Miller | C17: sydney.miller12@example.com | D17: (404) 555-1012 | E17: Marietta | F17: 46067 | G17: 345.33 | H17: Pending | I17: =COUNTIF($A$2:$A$141,A17) -> 1 | J17: =COUNTIFS(A$2:A17,A17,B$2:B17,B17,C$2:C17,IF(C17="","=",C17),D$2:D17,IF(D17="","=",D17),E$2:E17,IF(E17="","=",E17),F$2:F17,F17,G$2:G17,IF(G17="","=",G17),H$2:H17,H17) -> 1 | K17: =IF(OR(C17="",G17="",NOT(ISNUMBER(G17)),AND(ISNUMBER(G17),G17<=0)),"Needs Review","Valid") -> Valid
A18: C117 | B18: Parker Martin | C18: parker.martin117@example.com | D18: (404) 555-1117 | E18: Smyrna | F18: 46067 | G18: 243.54 | H18: Cancelled | I18: =COUNTIF($A$2:$A$141,A18) -> 1 | J18: =COUNTIFS(A$2:A18,A18,B$2:B18,B18,C$2:C18,IF(C18="","=",C18),D$2:D18,IF(D18="","=",D18),E$2:E18,IF(E18="","=",E18),F$2:F18,F18,G$2:G18,IF(G18="","=",G18),H$2:H18,H18) -> 1 | K18: =IF(OR(C18="",G18="",NOT(ISNUMBER(G18)),AND(ISNUMBER(G18),G18<=0)),"Needs Review","Valid") -> Valid
A19: C035 | B19: Sydney White | C19: sydney.white35@example.com | D19: (404) 555-1035 | E19: Kennesaw | F19: 46068 | G19: 349.18 | H19: Cancelled | I19: =COUNTIF($A$2:$A$141,A19) -> 1 | J19: =COUNTIFS(A$2:A19,A19,B$2:B19,B19,C$2:C19,IF(C19="","=",C19),D$2:D19,IF(D19="","=",D19),E$2:E19,IF(E19="","=",E19),F$2:F19,F19,G$2:G19,IF(G19="","=",G19),H$2:H19,H19) -> 1 | K19: =IF(OR(C19="",G19="",NOT(ISNUMBER(G19)),AND(ISNUMBER(G19),G19<=0)),"Needs Review","Valid") -> Valid
A20: C086 | B20: Robin Moore | C20: robin.moore86@example.com | D20: (404) 555-1086 | E20: Roswell | F20: 46069 | G20: 265.53 | H20: Completed | I20: =COUNTIF($A$2:$A$141,A20) -> 1 | J20: =COUNTIFS(A$2:A20,A20,B$2:B20,B20,C$2:C20,IF(C20="","=",C20),D$2:D20,IF(D20="","=",D20),E$2:E20,IF(E20="","=",E20),F$2:F20,F20,G$2:G20,IF(G20="","=",G20),H$2:H20,H20) -> 1 | K20: =IF(OR(C20="",G20="",NOT(ISNUMBER(G20)),AND(ISNUMBER(G20),G20<=0)),"Needs Review","Valid") -> Valid
A21: C027 | B21: Blake Johnson | C21: blake.johnson27@example.com | D21: (404) 555-1027 | E21: Kennesaw | F21: 46071 | G21: 156.72 | H21: Completed | I21: =COUNTIF($A$2:$A$141,A21) -> 1 | J21: =COUNTIFS(A$2:A21,A21,B$2:B21,B21,C$2:C21,IF(C21="","=",C21),D$2:D21,IF(D21="","=",D21),E$2:E21,IF(E21="","=",E21),F$2:F21,F21,G$2:G21,IF(G21="","=",G21),H$2:H21,H21) -> 1 | K21: =IF(OR(C21="",G21="",NOT(ISNUMBER(G21)),AND(ISNUMBER(G21),G21<=0)),"Needs Review","Valid") -> Valid
A22: C057 | B22: Taylor Martin | D22: (404) 555-1057 | E22: Atlanta | F22: 46076 | G22: 294.05 | H22: Processing | I22: =COUNTIF($A$2:$A$141,A22) -> 1 | J22: =COUNTIFS(A$2:A22,A22,B$2:B22,B22,C$2:C22,IF(C22="","=",C22),D$2:D22,IF(D22="","=",D22),E$2:E22,IF(E22="","=",E22),F$2:F22,F22,G$2:G22,IF(G22="","=",G22),H$2:H22,H22) -> 1 | K22: =IF(OR(C22="",G22="",NOT(ISNUMBER(G22)),AND(ISNUMBER(G22),G22<=0)),"Needs Review","Valid") -> Needs Review
A23: C041 | B23: Kendall Johnson | C23: kendall.johnson41@example.com | D23: (404) 555-1041 | E23: Douglasville | F23: 46082 | G23: 45.08 | H23: Completed | I23: =COUNTIF($A$2:$A$141,A23) -> 1 | J23: =COUNTIFS(A$2:A23,A23,B$2:B23,B23,C$2:C23,IF(C23="","=",C23),D$2:D23,IF(D23="","=",D23),E$2:E23,IF(E23="","=",E23),F$2:F23,F23,G$2:G23,IF(G23="","=",G23),H$2:H23,H23) -> 1 | K23: =IF(OR(C23="",G23="",NOT(ISNUMBER(G23)),AND(ISNUMBER(G23),G23<=0)),"Needs Review","Valid") -> Valid
A24: C021 | B24: Dakota Harris | C24: dakota.harris21@example.com | D24: (404) 555-1021 | E24: Douglasville | F24: 46085 | G24: 153.69 | H24: PENDING | I24: =COUNTIF($A$2:$A$141,A24) -> 1 | J24: =COUNTIFS(A$2:A24,A24,B$2:B24,B24,C$2:C24,IF(C24="","=",C24),D$2:D24,IF(D24="","=",D24),E$2:E24,IF(E24="","=",E24),F$2:F24,F24,G$2:G24,IF(G24="","=",G24),H$2:H24,H24) -> 1 | K24: =IF(OR(C24="",G24="",NOT(ISNUMBER(G24)),AND(ISNUMBER(G24),G24<=0)),"Needs Review","Valid") -> Valid
A25: C124 | B25: Devin Miller | C25: devin.miller124@example.com | D25: (404) 555-1124 | E25: Kennesaw | F25: 46088 | G25: 178.5 | H25: Completed | I25: =COUNTIF($A$2:$A$141,A25) -> 1 | J25: =COUNTIFS(A$2:A25,A25,B$2:B25,B25,C$2:C25,IF(C25="","=",C25),D$2:D25,IF(D25="","=",D25),E$2:E25,IF(E25="","=",E25),F$2:F25,F25,G$2:G25,IF(G25="","=",G25),H$2:H25,H25) -> 1 | K25: =IF(OR(C25="",G25="",NOT(ISNUMBER(G25)),AND(ISNUMBER(G25),G25<=0)),"Needs Review","Valid") -> Valid
A26: C062 | B26: Quinn Harris | C26: quinn.harris62@example.com | D26: (404) 555-1062 | E26: Sandy Springs | F26: 46092 | G26: 309.8 | H26: Pending | I26: =COUNTIF($A$2:$A$141,A26) -> 1 | J26: =COUNTIFS(A$2:A26,A26,B$2:B26,B26,C$2:C26,IF(C26="","=",C26),D$2:D26,IF(D26="","=",D26),E$2:E26,IF(E26="","=",E26),F$2:F26,F26,G$2:G26,IF(G26="","=",G26),H$2:H26,H26) -> 1 | K26: =IF(OR(C26="",G26="",NOT(ISNUMBER(G26)),AND(ISNUMBER(G26),G26<=0)),"Needs Review","Valid") -> Valid
A27: C044 | B27: Kendall White | C27: kendall.white44@example.com | D27: (404) 555-1044 | E27: Decatur | F27: 46094 | G27: 162.02 | H27: Cancelled | I27: =COUNTIF($A$2:$A$141,A27) -> 1 | J27: =COUNTIFS(A$2:A27,A27,B$2:B27,B27,C$2:C27,IF(C27="","=",C27),D$2:D27,IF(D27="","=",D27),E$2:E27,IF(E27="","=",E27),F$2:F27,F27,G$2:G27,IF(G27="","=",G27),H$2:H27,H27) -> 1 | K27: =IF(OR(C27="",G27="",NOT(ISNUMBER(G27)),AND(ISNUMBER(G27),G27<=0)),"Needs Review","Valid") -> Valid
A28: C079 | B28: Reese Anderson | C28: reese.anderson79@example.com | D28: (404) 555-1079 | E28: Sandy Springs | F28: 46096 | G28: 95.32 | H28: Cancelled | I28: =COUNTIF($A$2:$A$141,A28) -> 1 | J28: =COUNTIFS(A$2:A28,A28,B$2:B28,B28,C$2:C28,IF(C28="","=",C28),D$2:D28,IF(D28="","=",D28),E$2:E28,IF(E28="","=",E28),F$2:F28,F28,G$2:G28,IF(G28="","=",G28),H$2:H28,H28) -> 1 | K28: =IF(OR(C28="",G28="",NOT(ISNUMBER(G28)),AND(ISNUMBER(G28),G28<=0)),"Needs Review","Valid") -> Valid
A29: C053 | B29: Reese Martin | C29: reese.martin53@example.com | D29: (404) 555-1053 | E29: Douglasville | F29: 46096 | G29: 324.41 | H29: Pending | I29: =COUNTIF($A$2:$A$141,A29) -> 1 | J29: =COUNTIFS(A$2:A29,A29,B$2:B29,B29,C$2:C29,IF(C29="","=",C29),D$2:D29,IF(D29="","=",D29),E$2:E29,IF(E29="","=",E29),F$2:F29,F29,G$2:G29,IF(G29="","=",G29),H$2:H29,H29) -> 1 | K29: =IF(OR(C29="",G29="",NOT(ISNUMBER(G29)),AND(ISNUMBER(G29),G29<=0)),"Needs Review","Valid") -> Valid
A30: C006 | B30: Cameron Moore | C30: cameron.moore6@example.com | D30: (404) 555-1006 | E30: Roswell | F30: 46096 | G30: 334.3 | H30: Processing | I30: =COUNTIF($A$2:$A$141,A30) -> 1 | J30: =COUNTIFS(A$2:A30,A30,B$2:B30,B30,C$2:C30,IF(C30="","=",C30),D$2:D30,IF(D30="","=",D30),E$2:E30,IF(E30="","=",E30),F$2:F30,F30,G$2:G30,IF(G30="","=",G30),H$2:H30,H30) -> 1 | K30: =IF(OR(C30="",G30="",NOT(ISNUMBER(G30)),AND(ISNUMBER(G30),G30<=0)),"Needs Review","Valid") -> Valid
A31: C118 | B31: Alex Thompson | C31: alex.thompson118@example.com | D31: (404) 555-1118 | E31: Marietta | F31: 46099 | G31: 228.4 | H31: Completed | I31: =COUNTIF($A$2:$A$141,A31) -> 1 | J31: =COUNTIFS(A$2:A31,A31,B$2:B31,B31,C$2:C31,IF(C31="","=",C31),D$2:D31,IF(D31="","=",D31),E$2:E31,IF(E31="","=",E31),F$2:F31,F31,G$2:G31,IF(G31="","=",G31),H$2:H31,H31) -> 1 | K31: =IF(OR(C31="",G31="",NOT(ISNUMBER(G31)),AND(ISNUMBER(G31),G31<=0)),"Needs Review","Valid") -> Valid
A32: C108 | B32: Alex Williams | C32: alex.williams108@example.com | D32: (404) 555-1108 | E32: Decatur | F32: 46105 | G32: 236.5 | H32: Cancelled | I32: =COUNTIF($A$2:$A$141,A32) -> 1 | J32: =COUNTIFS(A$2:A32,A32,B$2:B32,B32,C$2:C32,IF(C32="","=",C32),D$2:D32,IF(D32="","=",D32),E$2:E32,IF(E32="","=",E32),F$2:F32,F32,G$2:G32,IF(G32="","=",G32),H$2:H32,H32) -> 1 | K32: =IF(OR(C32="",G32="",NOT(ISNUMBER(G32)),AND(ISNUMBER(G32),G32<=0)),"Needs Review","Valid") -> Valid
A33: C070 | B33: Riley Jackson | C33: riley.jackson70@example.com | D33: (404) 555-1070 | E33: Atlanta | F33: 46107 | G33: 254.93 | H33: Cancelled | I33: =COUNTIF($A$2:$A$141,A33) -> 1 | J33: =COUNTIFS(A$2:A33,A33,B$2:B33,B33,C$2:C33,IF(C33="","=",C33),D$2:D33,IF(D33="","=",D33),E$2:E33,IF(E33="","=",E33),F$2:F33,F33,G$2:G33,IF(G33="","=",G33),H$2:H33,H33) -> 1 | K33: =IF(OR(C33="",G33="",NOT(ISNUMBER(G33)),AND(ISNUMBER(G33),G33<=0)),"Needs Review","Valid") -> Valid
A34: C125 | B34: Reese Miller | C34: reese.miller125@example.com | D34: (404) 555-1125 | E34: Sandy Springs | F34: 46109 | G34: 174.03 | H34: Cancelled | I34: =COUNTIF($A$2:$A$141,A34) -> 1 | J34: =COUNTIFS(A$2:A34,A34,B$2:B34,B34,C$2:C34,IF(C34="","=",C34),D$2:D34,IF(D34="","=",D34),E$2:E34,IF(E34="","=",E34),F$2:F34,F34,G$2:G34,IF(G34="","=",G34),H$2:H34,H34) -> 1 | K34: =IF(OR(C34="",G34="",NOT(ISNUMBER(G34)),AND(ISNUMBER(G34),G34<=0)),"Needs Review","Valid") -> Valid
... A39: C069 | B39: Casey Anderson | C39: casey.anderson69@example.com | D39: (404) 555-1069 | E39: Atl | F39: 46117 | G39: 18.15 | H39: Pending | I39: =COUNTIF($A$2:$A$141,A39) -> 1 | J39: =COUNTIFS(A$2:A39,A39,B$2:B39,B39,C$2:C39,IF(C39="","=",C39),D$2:D39,IF(D39="","=",D39),E$2:E39,IF(E39="","=",E39),F$2:F39,F39,G$2:G39,IF(G39="","=",G39),H$2:H39,H39) -> 1 | K39: =IF(OR(C39="",G39="",NOT(ISNUMBER(G39)),AND(ISNUMBER(G39),G39<=0)),"Needs Review","Valid") -> Valid
A40: C114 | B40: Kendall Martin | D40: (404) 555-1114 | E40: Smyrna | F40: 46118 | G40: 172.53 | H40: Processing | I40: =COUNTIF($A$2:$A$141,A40) -> 1 | J40: =COUNTIFS(A$2:A40,A40,B$2:B40,B40,C$2:C40,IF(C40="","=",C40),D$2:D40,IF(D40="","=",D40),E$2:E40,IF(E40="","=",E40),F$2:F40,F40,G$2:G40,IF(G40="","=",G40),H$2:H40,H40) -> 1 | K40: =IF(OR(C40="",G40="",NOT(ISNUMBER(G40)),AND(ISNUMBER(G40),G40<=0)),"Needs Review","Valid") -> Needs Review
A41: C078 | B41: Drew Anderson | C41: drew.anderson78@example.com | D41: (404) 555-1078 | E41: Douglasville | F41: 46118 | G41: 309.19 | H41: Processing | I41: =COUNTIF($A$2:$A$141,A41) -> 1 | J41: =COUNTIFS(A$2:A41,A41,B$2:B41,B41,C$2:C41,IF(C41="","=",C41),D$2:D41,IF(D41="","=",D41),E$2:E41,IF(E41="","=",E41),F$2:F41,F41,G$2:G41,IF(G41="","=",G41),H$2:H41,H41) -> 1 | K41: =IF(OR(C41="",G41="",NOT(ISNUMBER(G41)),AND(ISNUMBER(G41),G41<=0)),"Needs Review","Valid") -> Valid
A42: C023 | B42: Sydney Davis | C42: sydney.davis23@example.com | D42: (404) 555-1023 | E42: Atl | F42: 46121 | G42: 305.63 | H42: Pending | I42: =COUNTIF($A$2:$A$141,A42) -> 1 | J42: =COUNTIFS(A$2:A42,A42,B$2:B42,B42,C$2:C42,IF(C42="","=",C42),D$2:D42,IF(D42="","=",D42),E$2:E42,IF(E42="","=",E42),F$2:F42,F42,G$2:G42,IF(G42="","=",G42),H$2:H42,H42) -> 1 | K42: =IF(OR(C42="",G42="",NOT(ISNUMBER(G42)),AND(ISNUMBER(G42),G42<=0)),"Needs Review","Valid") -> Valid
A43: C005 | B43: Drew Wilson | C43: drew.wilson5@example.com | D43: (404) 555-1005 | E43: Sandy Springs | F43: 46124 | G43: 213.82 | H43: Processing | I43: =COUNTIF($A$2:$A$141,A43) -> 1 | J43: =COUNTIFS(A$2:A43,A43,B$2:B43,B43,C$2:C43,IF(C43="","=",C43),D$2:D43,IF(D43="","=",D43),E$2:E43,IF(E43="","=",E43),F$2:F43,F43,G$2:G43,IF(G43="","=",G43),H$2:H43,H43) -> 1 | K43: =IF(OR(C43="",G43="",NOT(ISNUMBER(G43)),AND(ISNUMBER(G43),G43<=0)),"Needs Review","Valid") -> Valid
A44: C095 | B44: Riley Martin | D44: (404) 555-1095 | E44: Marietta | F44: 46125 | G44: 208.35 | H44: Pending | I44: =COUNTIF($A$2:$A$141,A44) -> 1 | J44: =COUNTIFS(A$2:A44,A44,B$2:B44,B44,C$2:C44,IF(C44="","=",C44),D$2:D44,IF(D44="","=",D44),E$2:E44,IF(E44="","=",E44),F$2:F44,F44,G$2:G44,IF(G44="","=",G44),H$2:H44,H44) -> 1 | K44: =IF(OR(C44="",G44="",NOT(ISNUMBER(G44)),AND(ISNUMBER(G44),G44<=0)),"Needs Review","Valid") -> Needs Review
...

Sheet Data Validation
A1: Data Validation Report
A3: Validation Check | B3: Result
A4: Missing Customer IDs | B4: =COUNTBLANK('Cleaned Data'!A2:A141) -> 0
A5: Missing Email Adrresses | B5: =COUNTBLANK('Cleaned Data'!C2:C141) -> 7
A6: Invalid Order Amounts | B6: =COUNTBLANK('Cleaned Data'!G2:G141)+COUNTIF('Cleaned Data'!G2:G141,"<0") -> 4
A7: Invalid Order Statuses | B7: =COUNTIFS('Cleaned Data'!H2:H141,"<>Completed",'Cleaned Data'!H2:H141,"<>Pending",'Cleaned Data'!H2:H141,"<>Processing",'Cleaned Data'!H2:H141,"<>Cancelled") -> 0
A8: Total Validation Issues | B8: =SUM(B4:B7) -> 11

Sheet Audit Summary
A1: SUMMIT RETAIL | DATA QUALITY AUDIT
A3: Total Records | B3: =COUNTA('Cleaned Data'!A2:A141) -> 140
A4: Records with Repeated IDs | B4: =COUNTIF(tbl_CleanedData[Duplicate Check],">1") -> 0
A5: Original Exact Duplicate Rows | B5: 9
A6: Records Removed | B6: =150-B3 -> 10
A8: Completed Order Revenue | B8: =SUMIF('Cleaned Data'!H2:H141,"Completed",'Cleaned Data'!G2:G141) -> 5949.12
A10: Customer ID Lookup | B10: C109
A11: Customer Name | B11: =_xlfn.XLOOKUP(B10,'Cleaned Data'!A2:A141,'Cleaned Data'!B2:B141,"Not Found") -> Dakota Jackson
A13: Data Quality Reviiew
A14: Records Needing Review | B14: =COUNTIF('Cleaned Data'!K2:K141,"Needs Review") -> 11
A15: Valid Records | B15: =COUNTIF('Cleaned Data'!K2:K141,"Valid") -> 129
A17: Remaining Exact Duplicates | B17: =COUNTIF('Cleaned Data'!J2:J141,">1") -> 0
A19: Audit Notes
A20: Seven records contain missing email addresses, and four records contain missing order amounts. All 11 affected records have been flagged for manual review. No remaining exact duplicate records were detected.
